[2024-04-17T14:41:53.766+0000] {local_task_job_runner.py:120} INFO - ::group::Pre task execution logs
[2024-04-17T14:41:53.874+0000] {taskinstance.py:2073} INFO - Dependencies all met for dep_context=non-requeueable deps ti=<TaskInstance: eksplorasi_data_ingest.extract scheduled__2024-04-16T00:00:00+00:00 [queued]>
[2024-04-17T14:41:53.902+0000] {taskinstance.py:2073} INFO - Dependencies all met for dep_context=requeueable deps ti=<TaskInstance: eksplorasi_data_ingest.extract scheduled__2024-04-16T00:00:00+00:00 [queued]>
[2024-04-17T14:41:53.918+0000] {taskinstance.py:2303} INFO - Starting attempt 2 of 4
[2024-04-17T14:41:53.984+0000] {taskinstance.py:2327} INFO - Executing <Task(PythonOperator): extract> on 2024-04-16 00:00:00+00:00
[2024-04-17T14:41:54.029+0000] {warnings.py:110} WARNING - /home/***/.local/lib/python3.12/site-packages/***/task/task_runner/standard_task_runner.py:61: DeprecationWarning: This process (pid=577) is multi-threaded, use of fork() may lead to deadlocks in the child.
  pid = os.fork()

[2024-04-17T14:41:54.029+0000] {standard_task_runner.py:90} INFO - Running: ['***', 'tasks', 'run', 'eksplorasi_data_ingest', 'extract', 'scheduled__2024-04-16T00:00:00+00:00', '--job-id', '9', '--raw', '--subdir', 'DAGS_FOLDER/eksplorasi.py', '--cfg-path', '/tmp/tmpaob_w3kw']
[2024-04-17T14:41:54.032+0000] {standard_task_runner.py:91} INFO - Job 9: Subtask extract
[2024-04-17T14:41:54.031+0000] {standard_task_runner.py:63} INFO - Started process 585 to run task
[2024-04-17T14:41:54.925+0000] {task_command.py:426} INFO - Running <TaskInstance: eksplorasi_data_ingest.extract scheduled__2024-04-16T00:00:00+00:00 [running]> on host 072c8d84e657
[2024-04-17T14:41:55.158+0000] {taskinstance.py:2644} INFO - Exporting env vars: AIRFLOW_CTX_DAG_OWNER='yazid' AIRFLOW_CTX_DAG_ID='eksplorasi_data_ingest' AIRFLOW_CTX_TASK_ID='extract' AIRFLOW_CTX_EXECUTION_DATE='2024-04-16T00:00:00+00:00' AIRFLOW_CTX_TRY_NUMBER='2' AIRFLOW_CTX_DAG_RUN_ID='scheduled__2024-04-16T00:00:00+00:00'
[2024-04-17T14:41:55.161+0000] {taskinstance.py:430} INFO - ::endgroup::
[2024-04-17T14:41:56.198+0000] {python.py:237} INFO - Done. Returned value was: [{'id': 1, 'title': 'The Quantum Experiment', 'author': 'Alice Thompson', 'year': 2018, 'genre': 'Science Fiction'}, {'id': 2, 'title': 'Echoes of Infinity', 'author': 'Benjamin Rodriguez', 'year': 2021, 'genre': 'Fantasy'}, {'id': 3, 'title': 'Cipher of Shadows', 'author': 'Catherine White', 'year': 2019, 'genre': 'Mystery'}, {'id': 4, 'title': 'Astral Journey', 'author': 'David Turner', 'year': 2020, 'genre': 'Adventure'}, {'id': 5, 'title': 'Temporal Paradox', 'author': 'Emily Harris', 'year': 2017, 'genre': 'Science Fiction'}, {'id': 6, 'title': 'Whispers in the Dark', 'author': 'Frank Miller', 'year': 2022, 'genre': 'Horror'}, {'id': 7, 'title': 'Celestial Harmony', 'author': 'Grace Anderson', 'year': 2016, 'genre': 'Fantasy'}, {'id': 8, 'title': 'Lost Constellations', 'author': 'Henry Carter', 'year': 2015, 'genre': 'Adventure'}, {'id': 9, 'title': 'Chronicles of Light', 'author': 'Isabel Martinez', 'year': 2023, 'genre': 'Science Fiction'}, {'id': 10, 'title': 'Eternal Echo', 'author': 'Jack Robinson', 'year': 2018, 'genre': 'Fantasy'}, {'id': 11, 'title': 'Shadowed Secrets', 'author': 'Karen Brown', 'year': 2021, 'genre': 'Mystery'}, {'id': 12, 'title': 'Voyage Beyond Time', 'author': 'Liam Davis', 'year': 2019, 'genre': 'Adventure'}, {'id': 13, 'title': 'Galactic Whispers', 'author': 'Mia Thompson', 'year': 2020, 'genre': 'Science Fiction'}, {'id': 14, 'title': 'Cursed Crypt', 'author': 'Nathan Scott', 'year': 2017, 'genre': 'Horror'}, {'id': 15, 'title': 'Enchanted Realms', 'author': 'Olivia White', 'year': 2022, 'genre': 'Fantasy'}, {'id': 16, 'title': 'Journey to the Unknown', 'author': 'Paul Adams', 'year': 2016, 'genre': 'Adventure'}, {'id': 17, 'title': 'Spectral Symphony', 'author': 'Quinn Robinson', 'year': 2015, 'genre': 'Science Fiction'}, {'id': 18, 'title': 'Ephemeral Echoes', 'author': 'Rachel Miller', 'year': 2023, 'genre': 'Fantasy'}, {'id': 19, 'title': 'Cryptic Chronicles', 'author': 'Samuel Carter', 'year': 2018, 'genre': 'Mystery'}, {'id': 20, 'title': "Infinity's Embrace", 'author': 'Tessa Davis', 'year': 2021, 'genre': 'Adventure'}, {'id': 21, 'title': 'Whispers of the Stars', 'author': 'Ulysses Anderson', 'year': 2019, 'genre': 'Science Fiction'}, {'id': 22, 'title': 'Dark Descent', 'author': 'Violet Martinez', 'year': 2020, 'genre': 'Horror'}, {'id': 23, 'title': 'Mystic Mosaic', 'author': 'William Scott', 'year': 2017, 'genre': 'Fantasy'}, {'id': 24, 'title': 'Lost Legends', 'author': 'Xavier White', 'year': 2022, 'genre': 'Mystery'}, {'id': 25, 'title': 'Abyssal Adventures', 'author': 'Yvonne Adams', 'year': 2016, 'genre': 'Adventure'}, {'id': 26, 'title': 'Quasar Quest', 'author': 'Zane Brown', 'year': 2015, 'genre': 'Science Fiction'}, {'id': 27, 'title': 'Labyrinth of Shadows', 'author': 'Alice Thompson Jr.', 'year': 2023, 'genre': 'Fantasy'}, {'id': 28, 'title': 'Eternal Eclipse', 'author': 'Benjamin Rodriguez Jr.', 'year': 2018, 'genre': 'Horror'}, {'id': 29, 'title': 'Secrets of the Spheres', 'author': 'Catherine White Jr.', 'year': 2021, 'genre': 'Mystery'}, {'id': 30, 'title': 'Vortex Voyage', 'author': 'David Turner Jr.', 'year': 2019, 'genre': 'Adventure'}, {'id': 31, 'title': 'Parallel Paradox', 'author': 'Emily Harris Jr.', 'year': 2020, 'genre': 'Science Fiction'}, {'id': 32, 'title': 'Whispers Reborn', 'author': 'Frank Miller Jr.', 'year': 2017, 'genre': 'Fantasy'}, {'id': 33, 'title': 'Celestial Serenade', 'author': 'Grace Anderson Jr.', 'year': 2022, 'genre': 'Mystery'}, {'id': 34, 'title': 'Found Constellations', 'author': 'Henry Carter Jr.', 'year': 2016, 'genre': 'Adventure'}, {'id': 35, 'title': 'Chronicles of Darkness', 'author': 'Isabel Martinez Jr.', 'year': 2015, 'genre': 'Science Fiction'}, {'id': 36, 'title': 'Eternal Echoes Returned', 'author': 'Jack Robinson Jr.', 'year': 2023, 'genre': 'Fantasy'}, {'id': 37, 'title': 'Shadowed Secrets Unveiled', 'author': 'Karen Brown Jr.', 'year': 2018, 'genre': 'Mystery'}, {'id': 38, 'title': 'Voyage Beyond Time Redux', 'author': 'Liam Davis Jr.', 'year': 2021, 'genre': 'Adventure'}, {'id': 39, 'title': 'Galactic Whispers Resurfaced', 'author': 'Mia Thompson Jr.', 'year': 2019, 'genre': 'Science Fiction'}, {'id': 40, 'title': 'Cursed Crypt Revisited', 'author': 'Nathan Scott Jr.', 'year': 2020, 'genre': 'Horror'}, {'id': 41, 'title': 'Enchanted Realms Rediscovered', 'author': 'Olivia White Jr.', 'year': 2017, 'genre': 'Fantasy'}, {'id': 42, 'title': 'Journey to the Unknown Continued', 'author': 'Paul Adams Jr.', 'year': 2022, 'genre': 'Adventure'}, {'id': 43, 'title': 'Spectral Symphony Replayed', 'author': 'Quinn Robinson Jr.', 'year': 2016, 'genre': 'Science Fiction'}, {'id': 44, 'title': 'Ephemeral Echoes Echoed', 'author': 'Rachel Miller Jr.', 'year': 2023, 'genre': 'Fantasy'}, {'id': 45, 'title': 'Cryptic Chronicles Continued', 'author': 'Samuel Carter Jr.', 'year': 2018, 'genre': 'Mystery'}, {'id': 46, 'title': "Infinity's Embrace Extended", 'author': 'Tessa Davis Jr.', 'year': 2021, 'genre': 'Adventure'}, {'id': 47, 'title': 'Whispers of the Stars Reimagined', 'author': 'Ulysses Anderson Jr.', 'year': 2019, 'genre': 'Science Fiction'}, {'id': 48, 'title': 'Dark Descent Revived', 'author': 'Violet Martinez Jr.', 'year': 2020, 'genre': 'Horror'}, {'id': 49, 'title': 'Mystic Mosaic Mended', 'author': 'William Scott Jr.', 'year': 2017, 'genre': 'Fantasy'}, {'id': 50, 'title': 'Lost Legends Continued', 'author': 'Xavier White Jr.', 'year': 2022, 'genre': 'Mystery'}]
[2024-04-17T14:41:56.214+0000] {taskinstance.py:441} INFO - ::group::Post task execution logs
[2024-04-17T14:42:28.974+0000] {taskinstance.py:2890} ERROR - Task failed with exception
Traceback (most recent call last):
  File "/home/airflow/.local/lib/python3.12/site-packages/sqlalchemy/engine/base.py", line 3371, in _wrap_pool_connect
    return fn()
           ^^^^
  File "/home/airflow/.local/lib/python3.12/site-packages/sqlalchemy/pool/base.py", line 327, in connect
    return _ConnectionFairy._checkout(self)
           ^^^^^^^^^^^^^^^^^^^^^^^^^^^^^^^^
  File "/home/airflow/.local/lib/python3.12/site-packages/sqlalchemy/pool/base.py", line 894, in _checkout
    fairy = _ConnectionRecord.checkout(pool)
            ^^^^^^^^^^^^^^^^^^^^^^^^^^^^^^^^
  File "/home/airflow/.local/lib/python3.12/site-packages/sqlalchemy/pool/base.py", line 493, in checkout
    rec = pool._do_get()
          ^^^^^^^^^^^^^^
  File "/home/airflow/.local/lib/python3.12/site-packages/sqlalchemy/pool/impl.py", line 256, in _do_get
    return self._create_connection()
           ^^^^^^^^^^^^^^^^^^^^^^^^^
  File "/home/airflow/.local/lib/python3.12/site-packages/sqlalchemy/pool/base.py", line 273, in _create_connection
    return _ConnectionRecord(self)
           ^^^^^^^^^^^^^^^^^^^^^^^
  File "/home/airflow/.local/lib/python3.12/site-packages/sqlalchemy/pool/base.py", line 388, in __init__
    self.__connect()
  File "/home/airflow/.local/lib/python3.12/site-packages/sqlalchemy/pool/base.py", line 690, in __connect
    with util.safe_reraise():
  File "/home/airflow/.local/lib/python3.12/site-packages/sqlalchemy/util/langhelpers.py", line 70, in __exit__
    compat.raise_(
  File "/home/airflow/.local/lib/python3.12/site-packages/sqlalchemy/util/compat.py", line 211, in raise_
    raise exception
  File "/home/airflow/.local/lib/python3.12/site-packages/sqlalchemy/pool/base.py", line 686, in __connect
    self.dbapi_connection = connection = pool._invoke_creator(self)
                                         ^^^^^^^^^^^^^^^^^^^^^^^^^^
  File "/home/airflow/.local/lib/python3.12/site-packages/sqlalchemy/engine/create.py", line 574, in connect
    return dialect.connect(*cargs, **cparams)
           ^^^^^^^^^^^^^^^^^^^^^^^^^^^^^^^^^^
  File "/home/airflow/.local/lib/python3.12/site-packages/sqlalchemy/engine/default.py", line 598, in connect
    return self.dbapi.connect(*cargs, **cparams)
           ^^^^^^^^^^^^^^^^^^^^^^^^^^^^^^^^^^^^^
  File "/home/airflow/.local/lib/python3.12/site-packages/psycopg2/__init__.py", line 122, in connect
    conn = _connect(dsn, connection_factory=connection_factory, **kwasync)
           ^^^^^^^^^^^^^^^^^^^^^^^^^^^^^^^^^^^^^^^^^^^^^^^^^^^^^^^^^^^^^^^
psycopg2.OperationalError: could not translate host name "postgres" to address: Temporary failure in name resolution


The above exception was the direct cause of the following exception:

Traceback (most recent call last):
  File "/home/airflow/.local/lib/python3.12/site-packages/airflow/models/taskinstance.py", line 2478, in _run_raw_task
    self.refresh_from_db(lock_for_update=True, session=session)
  File "/home/airflow/.local/lib/python3.12/site-packages/airflow/utils/session.py", line 76, in wrapper
    return func(*args, **kwargs)
           ^^^^^^^^^^^^^^^^^^^^^
  File "/home/airflow/.local/lib/python3.12/site-packages/airflow/models/taskinstance.py", line 1818, in refresh_from_db
    _refresh_from_db(task_instance=self, session=session, lock_for_update=lock_for_update)
  File "/home/airflow/.local/lib/python3.12/site-packages/airflow/models/taskinstance.py", line 510, in _refresh_from_db
    ti = TaskInstance.get_task_instance(
         ^^^^^^^^^^^^^^^^^^^^^^^^^^^^^^^
  File "/home/airflow/.local/lib/python3.12/site-packages/airflow/api_internal/internal_api_call.py", line 115, in wrapper
    return func(*args, **kwargs)
           ^^^^^^^^^^^^^^^^^^^^^
  File "/home/airflow/.local/lib/python3.12/site-packages/airflow/utils/session.py", line 76, in wrapper
    return func(*args, **kwargs)
           ^^^^^^^^^^^^^^^^^^^^^
  File "/home/airflow/.local/lib/python3.12/site-packages/airflow/models/taskinstance.py", line 1800, in get_task_instance
    for attempt in run_with_db_retries(logger=cls.logger()):
  File "/home/airflow/.local/lib/python3.12/site-packages/tenacity/__init__.py", line 347, in __iter__
    do = self.iter(retry_state=retry_state)
         ^^^^^^^^^^^^^^^^^^^^^^^^^^^^^^^^^^
  File "/home/airflow/.local/lib/python3.12/site-packages/tenacity/__init__.py", line 325, in iter
    raise retry_exc.reraise()
          ^^^^^^^^^^^^^^^^^^^
  File "/home/airflow/.local/lib/python3.12/site-packages/tenacity/__init__.py", line 158, in reraise
    raise self.last_attempt.result()
          ^^^^^^^^^^^^^^^^^^^^^^^^^^
  File "/usr/local/lib/python3.12/concurrent/futures/_base.py", line 449, in result
    return self.__get_result()
           ^^^^^^^^^^^^^^^^^^^
  File "/usr/local/lib/python3.12/concurrent/futures/_base.py", line 401, in __get_result
    raise self._exception
  File "/home/airflow/.local/lib/python3.12/site-packages/airflow/models/taskinstance.py", line 1802, in get_task_instance
    return query.with_for_update().one_or_none()
           ^^^^^^^^^^^^^^^^^^^^^^^^^^^^^^^^^^^^^
  File "/home/airflow/.local/lib/python3.12/site-packages/sqlalchemy/orm/query.py", line 2850, in one_or_none
    return self._iter().one_or_none()
           ^^^^^^^^^^^^
  File "/home/airflow/.local/lib/python3.12/site-packages/sqlalchemy/orm/query.py", line 2916, in _iter
    result = self.session.execute(
             ^^^^^^^^^^^^^^^^^^^^^
  File "/home/airflow/.local/lib/python3.12/site-packages/sqlalchemy/orm/session.py", line 1716, in execute
    conn = self._connection_for_bind(bind)
           ^^^^^^^^^^^^^^^^^^^^^^^^^^^^^^^
  File "/home/airflow/.local/lib/python3.12/site-packages/sqlalchemy/orm/session.py", line 1555, in _connection_for_bind
    return self._transaction._connection_for_bind(
           ^^^^^^^^^^^^^^^^^^^^^^^^^^^^^^^^^^^^^^^
  File "/home/airflow/.local/lib/python3.12/site-packages/sqlalchemy/orm/session.py", line 750, in _connection_for_bind
    conn = bind.connect()
           ^^^^^^^^^^^^^^
  File "/home/airflow/.local/lib/python3.12/site-packages/sqlalchemy/future/engine.py", line 412, in connect
    return super(Engine, self).connect()
           ^^^^^^^^^^^^^^^^^^^^^^^^^^^^^
  File "/home/airflow/.local/lib/python3.12/site-packages/sqlalchemy/engine/base.py", line 3325, in connect
    return self._connection_cls(self, close_with_result=close_with_result)
           ^^^^^^^^^^^^^^^^^^^^^^^^^^^^^^^^^^^^^^^^^^^^^^^^^^^^^^^^^^^^^^^
  File "/home/airflow/.local/lib/python3.12/site-packages/sqlalchemy/engine/base.py", line 96, in __init__
    else engine.raw_connection()
         ^^^^^^^^^^^^^^^^^^^^^^^
  File "/home/airflow/.local/lib/python3.12/site-packages/sqlalchemy/engine/base.py", line 3404, in raw_connection
    return self._wrap_pool_connect(self.pool.connect, _connection)
           ^^^^^^^^^^^^^^^^^^^^^^^^^^^^^^^^^^^^^^^^^^^^^^^^^^^^^^^
  File "/home/airflow/.local/lib/python3.12/site-packages/sqlalchemy/engine/base.py", line 3374, in _wrap_pool_connect
    Connection._handle_dbapi_exception_noconnection(
  File "/home/airflow/.local/lib/python3.12/site-packages/sqlalchemy/engine/base.py", line 2208, in _handle_dbapi_exception_noconnection
    util.raise_(
  File "/home/airflow/.local/lib/python3.12/site-packages/sqlalchemy/util/compat.py", line 211, in raise_
    raise exception
  File "/home/airflow/.local/lib/python3.12/site-packages/sqlalchemy/engine/base.py", line 3371, in _wrap_pool_connect
    return fn()
           ^^^^
  File "/home/airflow/.local/lib/python3.12/site-packages/sqlalchemy/pool/base.py", line 327, in connect
    return _ConnectionFairy._checkout(self)
           ^^^^^^^^^^^^^^^^^^^^^^^^^^^^^^^^
  File "/home/airflow/.local/lib/python3.12/site-packages/sqlalchemy/pool/base.py", line 894, in _checkout
    fairy = _ConnectionRecord.checkout(pool)
            ^^^^^^^^^^^^^^^^^^^^^^^^^^^^^^^^
  File "/home/airflow/.local/lib/python3.12/site-packages/sqlalchemy/pool/base.py", line 493, in checkout
    rec = pool._do_get()
          ^^^^^^^^^^^^^^
  File "/home/airflow/.local/lib/python3.12/site-packages/sqlalchemy/pool/impl.py", line 256, in _do_get
    return self._create_connection()
           ^^^^^^^^^^^^^^^^^^^^^^^^^
  File "/home/airflow/.local/lib/python3.12/site-packages/sqlalchemy/pool/base.py", line 273, in _create_connection
    return _ConnectionRecord(self)
           ^^^^^^^^^^^^^^^^^^^^^^^
  File "/home/airflow/.local/lib/python3.12/site-packages/sqlalchemy/pool/base.py", line 388, in __init__
    self.__connect()
  File "/home/airflow/.local/lib/python3.12/site-packages/sqlalchemy/pool/base.py", line 690, in __connect
    with util.safe_reraise():
  File "/home/airflow/.local/lib/python3.12/site-packages/sqlalchemy/util/langhelpers.py", line 70, in __exit__
    compat.raise_(
  File "/home/airflow/.local/lib/python3.12/site-packages/sqlalchemy/util/compat.py", line 211, in raise_
    raise exception
  File "/home/airflow/.local/lib/python3.12/site-packages/sqlalchemy/pool/base.py", line 686, in __connect
    self.dbapi_connection = connection = pool._invoke_creator(self)
                                         ^^^^^^^^^^^^^^^^^^^^^^^^^^
  File "/home/airflow/.local/lib/python3.12/site-packages/sqlalchemy/engine/create.py", line 574, in connect
    return dialect.connect(*cargs, **cparams)
           ^^^^^^^^^^^^^^^^^^^^^^^^^^^^^^^^^^
  File "/home/airflow/.local/lib/python3.12/site-packages/sqlalchemy/engine/default.py", line 598, in connect
    return self.dbapi.connect(*cargs, **cparams)
           ^^^^^^^^^^^^^^^^^^^^^^^^^^^^^^^^^^^^^
  File "/home/airflow/.local/lib/python3.12/site-packages/psycopg2/__init__.py", line 122, in connect
    conn = _connect(dsn, connection_factory=connection_factory, **kwasync)
           ^^^^^^^^^^^^^^^^^^^^^^^^^^^^^^^^^^^^^^^^^^^^^^^^^^^^^^^^^^^^^^^
sqlalchemy.exc.OperationalError: (psycopg2.OperationalError) could not translate host name "postgres" to address: Temporary failure in name resolution

(Background on this error at: https://sqlalche.me/e/14/e3q8)
[2024-04-17T14:42:29.601+0000] {job.py:218} ERROR - Job heartbeat got an exception
Traceback (most recent call last):
  File "/home/airflow/.local/lib/python3.12/site-packages/sqlalchemy/engine/base.py", line 3371, in _wrap_pool_connect
    return fn()
           ^^^^
  File "/home/airflow/.local/lib/python3.12/site-packages/sqlalchemy/pool/base.py", line 327, in connect
    return _ConnectionFairy._checkout(self)
           ^^^^^^^^^^^^^^^^^^^^^^^^^^^^^^^^
  File "/home/airflow/.local/lib/python3.12/site-packages/sqlalchemy/pool/base.py", line 894, in _checkout
    fairy = _ConnectionRecord.checkout(pool)
            ^^^^^^^^^^^^^^^^^^^^^^^^^^^^^^^^
  File "/home/airflow/.local/lib/python3.12/site-packages/sqlalchemy/pool/base.py", line 493, in checkout
    rec = pool._do_get()
          ^^^^^^^^^^^^^^
  File "/home/airflow/.local/lib/python3.12/site-packages/sqlalchemy/pool/impl.py", line 256, in _do_get
    return self._create_connection()
           ^^^^^^^^^^^^^^^^^^^^^^^^^
  File "/home/airflow/.local/lib/python3.12/site-packages/sqlalchemy/pool/base.py", line 273, in _create_connection
    return _ConnectionRecord(self)
           ^^^^^^^^^^^^^^^^^^^^^^^
  File "/home/airflow/.local/lib/python3.12/site-packages/sqlalchemy/pool/base.py", line 388, in __init__
    self.__connect()
  File "/home/airflow/.local/lib/python3.12/site-packages/sqlalchemy/pool/base.py", line 690, in __connect
    with util.safe_reraise():
  File "/home/airflow/.local/lib/python3.12/site-packages/sqlalchemy/util/langhelpers.py", line 70, in __exit__
    compat.raise_(
  File "/home/airflow/.local/lib/python3.12/site-packages/sqlalchemy/util/compat.py", line 211, in raise_
    raise exception
  File "/home/airflow/.local/lib/python3.12/site-packages/sqlalchemy/pool/base.py", line 686, in __connect
    self.dbapi_connection = connection = pool._invoke_creator(self)
                                         ^^^^^^^^^^^^^^^^^^^^^^^^^^
  File "/home/airflow/.local/lib/python3.12/site-packages/sqlalchemy/engine/create.py", line 574, in connect
    return dialect.connect(*cargs, **cparams)
           ^^^^^^^^^^^^^^^^^^^^^^^^^^^^^^^^^^
  File "/home/airflow/.local/lib/python3.12/site-packages/sqlalchemy/engine/default.py", line 598, in connect
    return self.dbapi.connect(*cargs, **cparams)
           ^^^^^^^^^^^^^^^^^^^^^^^^^^^^^^^^^^^^^
  File "/home/airflow/.local/lib/python3.12/site-packages/psycopg2/__init__.py", line 122, in connect
    conn = _connect(dsn, connection_factory=connection_factory, **kwasync)
           ^^^^^^^^^^^^^^^^^^^^^^^^^^^^^^^^^^^^^^^^^^^^^^^^^^^^^^^^^^^^^^^
psycopg2.OperationalError: could not translate host name "postgres" to address: Temporary failure in name resolution


The above exception was the direct cause of the following exception:

Traceback (most recent call last):
  File "/home/airflow/.local/lib/python3.12/site-packages/airflow/jobs/job.py", line 192, in heartbeat
    self._merge_from(Job._fetch_from_db(self, session))
                     ^^^^^^^^^^^^^^^^^^^^^^^^^^^^^^^^^
  File "/home/airflow/.local/lib/python3.12/site-packages/airflow/api_internal/internal_api_call.py", line 115, in wrapper
    return func(*args, **kwargs)
           ^^^^^^^^^^^^^^^^^^^^^
  File "/home/airflow/.local/lib/python3.12/site-packages/airflow/utils/session.py", line 76, in wrapper
    return func(*args, **kwargs)
           ^^^^^^^^^^^^^^^^^^^^^
  File "/home/airflow/.local/lib/python3.12/site-packages/airflow/utils/retries.py", line 89, in wrapped_function
    for attempt in run_with_db_retries(max_retries=retries, logger=logger, **retry_kwargs):
  File "/home/airflow/.local/lib/python3.12/site-packages/tenacity/__init__.py", line 347, in __iter__
    do = self.iter(retry_state=retry_state)
         ^^^^^^^^^^^^^^^^^^^^^^^^^^^^^^^^^^
  File "/home/airflow/.local/lib/python3.12/site-packages/tenacity/__init__.py", line 325, in iter
    raise retry_exc.reraise()
          ^^^^^^^^^^^^^^^^^^^
  File "/home/airflow/.local/lib/python3.12/site-packages/tenacity/__init__.py", line 158, in reraise
    raise self.last_attempt.result()
          ^^^^^^^^^^^^^^^^^^^^^^^^^^
  File "/usr/local/lib/python3.12/concurrent/futures/_base.py", line 449, in result
    return self.__get_result()
           ^^^^^^^^^^^^^^^^^^^
  File "/usr/local/lib/python3.12/concurrent/futures/_base.py", line 401, in __get_result
    raise self._exception
  File "/home/airflow/.local/lib/python3.12/site-packages/airflow/utils/retries.py", line 98, in wrapped_function
    return func(*args, **kwargs)
           ^^^^^^^^^^^^^^^^^^^^^
  File "/home/airflow/.local/lib/python3.12/site-packages/airflow/jobs/job.py", line 316, in _fetch_from_db
    session.merge(job)
  File "/home/airflow/.local/lib/python3.12/site-packages/sqlalchemy/orm/session.py", line 3056, in merge
    return self._merge(
           ^^^^^^^^^^^^
  File "/home/airflow/.local/lib/python3.12/site-packages/sqlalchemy/orm/session.py", line 3136, in _merge
    merged = self.get(
             ^^^^^^^^^
  File "/home/airflow/.local/lib/python3.12/site-packages/sqlalchemy/orm/session.py", line 2853, in get
    return self._get_impl(
           ^^^^^^^^^^^^^^^
  File "/home/airflow/.local/lib/python3.12/site-packages/sqlalchemy/orm/session.py", line 2975, in _get_impl
    return db_load_fn(
           ^^^^^^^^^^^
  File "/home/airflow/.local/lib/python3.12/site-packages/sqlalchemy/orm/loading.py", line 530, in load_on_pk_identity
    session.execute(
  File "/home/airflow/.local/lib/python3.12/site-packages/sqlalchemy/orm/session.py", line 1716, in execute
    conn = self._connection_for_bind(bind)
           ^^^^^^^^^^^^^^^^^^^^^^^^^^^^^^^
  File "/home/airflow/.local/lib/python3.12/site-packages/sqlalchemy/orm/session.py", line 1555, in _connection_for_bind
    return self._transaction._connection_for_bind(
           ^^^^^^^^^^^^^^^^^^^^^^^^^^^^^^^^^^^^^^^
  File "/home/airflow/.local/lib/python3.12/site-packages/sqlalchemy/orm/session.py", line 750, in _connection_for_bind
    conn = bind.connect()
           ^^^^^^^^^^^^^^
  File "/home/airflow/.local/lib/python3.12/site-packages/sqlalchemy/future/engine.py", line 412, in connect
    return super(Engine, self).connect()
           ^^^^^^^^^^^^^^^^^^^^^^^^^^^^^
  File "/home/airflow/.local/lib/python3.12/site-packages/sqlalchemy/engine/base.py", line 3325, in connect
    return self._connection_cls(self, close_with_result=close_with_result)
           ^^^^^^^^^^^^^^^^^^^^^^^^^^^^^^^^^^^^^^^^^^^^^^^^^^^^^^^^^^^^^^^
  File "/home/airflow/.local/lib/python3.12/site-packages/sqlalchemy/engine/base.py", line 96, in __init__
    else engine.raw_connection()
         ^^^^^^^^^^^^^^^^^^^^^^^
  File "/home/airflow/.local/lib/python3.12/site-packages/sqlalchemy/engine/base.py", line 3404, in raw_connection
    return self._wrap_pool_connect(self.pool.connect, _connection)
           ^^^^^^^^^^^^^^^^^^^^^^^^^^^^^^^^^^^^^^^^^^^^^^^^^^^^^^^
  File "/home/airflow/.local/lib/python3.12/site-packages/sqlalchemy/engine/base.py", line 3374, in _wrap_pool_connect
    Connection._handle_dbapi_exception_noconnection(
  File "/home/airflow/.local/lib/python3.12/site-packages/sqlalchemy/engine/base.py", line 2208, in _handle_dbapi_exception_noconnection
    util.raise_(
  File "/home/airflow/.local/lib/python3.12/site-packages/sqlalchemy/util/compat.py", line 211, in raise_
    raise exception
  File "/home/airflow/.local/lib/python3.12/site-packages/sqlalchemy/engine/base.py", line 3371, in _wrap_pool_connect
    return fn()
           ^^^^
  File "/home/airflow/.local/lib/python3.12/site-packages/sqlalchemy/pool/base.py", line 327, in connect
    return _ConnectionFairy._checkout(self)
           ^^^^^^^^^^^^^^^^^^^^^^^^^^^^^^^^
  File "/home/airflow/.local/lib/python3.12/site-packages/sqlalchemy/pool/base.py", line 894, in _checkout
    fairy = _ConnectionRecord.checkout(pool)
            ^^^^^^^^^^^^^^^^^^^^^^^^^^^^^^^^
  File "/home/airflow/.local/lib/python3.12/site-packages/sqlalchemy/pool/base.py", line 493, in checkout
    rec = pool._do_get()
          ^^^^^^^^^^^^^^
  File "/home/airflow/.local/lib/python3.12/site-packages/sqlalchemy/pool/impl.py", line 256, in _do_get
    return self._create_connection()
           ^^^^^^^^^^^^^^^^^^^^^^^^^
  File "/home/airflow/.local/lib/python3.12/site-packages/sqlalchemy/pool/base.py", line 273, in _create_connection
    return _ConnectionRecord(self)
           ^^^^^^^^^^^^^^^^^^^^^^^
  File "/home/airflow/.local/lib/python3.12/site-packages/sqlalchemy/pool/base.py", line 388, in __init__
    self.__connect()
  File "/home/airflow/.local/lib/python3.12/site-packages/sqlalchemy/pool/base.py", line 690, in __connect
    with util.safe_reraise():
  File "/home/airflow/.local/lib/python3.12/site-packages/sqlalchemy/util/langhelpers.py", line 70, in __exit__
    compat.raise_(
  File "/home/airflow/.local/lib/python3.12/site-packages/sqlalchemy/util/compat.py", line 211, in raise_
    raise exception
  File "/home/airflow/.local/lib/python3.12/site-packages/sqlalchemy/pool/base.py", line 686, in __connect
    self.dbapi_connection = connection = pool._invoke_creator(self)
                                         ^^^^^^^^^^^^^^^^^^^^^^^^^^
  File "/home/airflow/.local/lib/python3.12/site-packages/sqlalchemy/engine/create.py", line 574, in connect
    return dialect.connect(*cargs, **cparams)
           ^^^^^^^^^^^^^^^^^^^^^^^^^^^^^^^^^^
  File "/home/airflow/.local/lib/python3.12/site-packages/sqlalchemy/engine/default.py", line 598, in connect
    return self.dbapi.connect(*cargs, **cparams)
           ^^^^^^^^^^^^^^^^^^^^^^^^^^^^^^^^^^^^^
  File "/home/airflow/.local/lib/python3.12/site-packages/psycopg2/__init__.py", line 122, in connect
    conn = _connect(dsn, connection_factory=connection_factory, **kwasync)
           ^^^^^^^^^^^^^^^^^^^^^^^^^^^^^^^^^^^^^^^^^^^^^^^^^^^^^^^^^^^^^^^
sqlalchemy.exc.OperationalError: (psycopg2.OperationalError) could not translate host name "postgres" to address: Temporary failure in name resolution

(Background on this error at: https://sqlalche.me/e/14/e3q8)
[2024-04-17T14:42:30.013+0000] {job.py:226} ERROR - Job heartbeat failed with error. Scheduler is in unhealthy state
[2024-04-17T14:42:39.524+0000] {standard_task_runner.py:110} ERROR - Failed to execute job 9 for task extract ((psycopg2.OperationalError) could not translate host name "postgres" to address: Temporary failure in name resolution

(Background on this error at: https://sqlalche.me/e/14/e3q8); 585)
[2024-04-17T14:43:06.449+0000] {job.py:226} ERROR - Job heartbeat failed with error. Scheduler is in unhealthy state
[2024-04-17T14:43:06.474+0000] {local_task_job_runner.py:240} INFO - Task exited with return code 1
[2024-04-17T14:43:09.082+0000] {taskinstance.py:3482} INFO - 0 downstream tasks scheduled from follow-on schedule check
[2024-04-17T14:43:09.090+0000] {local_task_job_runner.py:222} INFO - ::endgroup::
