[2024-04-16T12:33:04.020+0000] {task_context_logger.py:104} WARNING - Marking task instance <TaskInstance: hello_airflow_dag.touch_our_works scheduled__2024-04-15T00:00:00+00:00 [queued]> stuck in queued as failed. If the task instance has available retries, it will be retried.
[2024-04-16T12:33:04.765+0000] {task_context_logger.py:104} ERROR - Executor reports task instance <TaskInstance: hello_airflow_dag.touch_our_works scheduled__2024-04-15T00:00:00+00:00 [queued]> finished (failed) although the task says it's queued. (Info: None) Was the task killed externally?
