[2024-04-24T07:25:56.905+0000] {task_context_logger.py:104} ERROR - Executor reports task instance <TaskInstance: ETL_pipeline.extract_data scheduled__2022-05-23T00:00:00+00:00 [queued]> finished (failed) although the task says it's queued. (Info: None) Was the task killed externally?
