[2024-04-15T16:23:20.981+0000] {task_context_logger.py:104} ERROR - Executor reports task instance <TaskInstance: hello_airflow_dag.touch_our_works scheduled__2024-04-13T00:00:00+00:00 [queued]> finished (failed) although the task says it's queued. (Info: None) Was the task killed externally?
