[2024-04-16T12:38:56.830+0000] {task_context_logger.py:104} ERROR - Executor reports task instance <TaskInstance: calculator_dag.calculate_sum scheduled__2024-04-15T00:00:00+00:00 [queued]> finished (failed) although the task says it's queued. (Info: None) Was the task killed externally?
